<?xml version="1.0" ?>
<!-- =================================================================================== -->
<!-- |    This document was autogenerated by xacro from robot.xacro                    | -->
<!-- |    EDITING THIS FILE BY HAND IS NOT RECOMMENDED                                 | -->
<!-- =================================================================================== -->
<robot name="my_first">
  <material name="black">
    <color rgba="0 0 0 1"/>
  </material>
  <material name="white">
    <color rgba="1 1 1 1"/>
  </material>
  <link name="base_link">
    <visual>
      <geometry>
        <cylinder length="0.6" radius="0.1"/>
      </geometry>
      <origin rpy="0 0 0" xyz="0 0 0.3"/>
      <material name="white"/>
    </visual>
  </link>
  <joint name="base_rigidity" type="fixed">
    <parent link="base_link"/>
    <child link="connector_base_link"/>
    <origin xyz="0 0 0.6"/>
  </joint>
  <link name="connector_base_link">
    <visual>
      <geometry>
        <sphere radius="0.1"/>
      </geometry>
      <origin rpy="0 0 0" xyz="0 0 0"/>
      <material name="white"/>
    </visual>
  </link>
  <joint name="end_first_link" type="continuous">
    <parent link="connector_base_link"/>
    <child link="first_link"/>
    <origin rpy="0 0 0" xyz="0 0 0.1"/>
  </joint>
  <link name="first_link">
    <visual>
      <geometry>
        <cylinder length="2.0" radius="0.1"/>
      </geometry>
      <origin rpy="0 0 0" xyz="0 0 1.0"/>
      <material name="black"/>
    </visual>
  </link>
  <joint name="first_rigidity" type="fixed">
    <parent link="first_link"/>
    <child link="connector_first_link"/>
    <origin xyz="0 0 2.0"/>
  </joint>
  <link name="connector_first_link">
    <visual>
      <geometry>
        <sphere radius="0.1"/>
      </geometry>
      <origin rpy="0 0 0" xyz="0 0 0"/>
      <material name="black"/>
    </visual>
  </link>
  <joint name="end_other_link" type="continuous">
    <parent link="connector_base_link"/>
    <child link="other_link"/>
    <origin rpy="1.5 0 0" xyz="0 0 0.1"/>
  </joint>
  <link name="other_link">
    <visual>
      <geometry>
        <cylinder length="0.5" radius="0.1"/>
      </geometry>
      <origin rpy="0 0 0" xyz="0 0 0.25"/>
      <material name="black"/>
    </visual>
  </link>
  <joint name="other_rigidity" type="fixed">
    <parent link="other_link"/>
    <child link="connector_other_link"/>
    <origin xyz="0 0 0.5"/>
  </joint>
  <link name="connector_other_link">
    <visual>
      <geometry>
        <sphere radius="0.1"/>
      </geometry>
      <origin rpy="0 0 0" xyz="0 0 0"/>
      <material name="black"/>
    </visual>
  </link>
  <joint name="end_second_link" type="continuous">
    <parent link="connector_first_link"/>
    <child link="second_link"/>
    <origin rpy="0 0 0" xyz="0 0 0.1"/>
  </joint>
  <link name="second_link">
    <visual>
      <geometry>
        <cylinder length="0.6" radius="0.1"/>
      </geometry>
      <origin rpy="0 0 0" xyz="0 0 0.3"/>
      <material name="white"/>
    </visual>
  </link>
  <joint name="second_rigidity" type="fixed">
    <parent link="second_link"/>
    <child link="connector_second_link"/>
    <origin xyz="0 0 0.6"/>
  </joint>
  <link name="connector_second_link">
    <visual>
      <geometry>
        <sphere radius="0.1"/>
      </geometry>
      <origin rpy="0 0 0" xyz="0 0 0"/>
      <material name="white"/>
    </visual>
  </link>
  <joint name="end_third_link" type="continuous">
    <parent link="connector_second_link"/>
    <child link="third_link"/>
    <origin rpy="0 0 0" xyz="0 0 0.1"/>
  </joint>
  <link name="third_link">
    <visual>
      <geometry>
        <cylinder length="0.6" radius="0.1"/>
      </geometry>
      <origin rpy="0 0 0" xyz="0 0 0.3"/>
      <material name="black"/>
    </visual>
  </link>
  <joint name="third_rigidity" type="fixed">
    <parent link="third_link"/>
    <child link="connector_third_link"/>
    <origin xyz="0 0 0.6"/>
  </joint>
  <link name="connector_third_link">
    <visual>
      <geometry>
        <sphere radius="0.1"/>
      </geometry>
      <origin rpy="0 0 0" xyz="0 0 0"/>
      <material name="black"/>
    </visual>
  </link>
</robot>

